<mujocoinclude>
    <body name="first" pos="0 0 0">
        <!--惯性-->
        <geom pos="0 0.2 0" size="0.001"/>
        <!--inertial pos="0.000259233 -3.3552e-06 0.0116129" quat="-0.476119 0.476083 0.52279 0.522826" mass="0.798614" diaginertia="0.00120156 0.00113744 0.0009388" /-->
        <joint name="linear_joint" type="slide" pos="0 0.2 0" axis="0 1 0" limited="true" range="-3.14158 3.14158" frictionloss="50" />
        <include file="straight-guidewire.xml"/>
        <joint name="rotate_joint" type="hinge" pos="0 0.2 0" axis="0 1 0" limited="true" range="-3.14158 3.14158" frictionloss="50" />
    </body>
</mujocoinclude>