<mujoco model="guidewire">
  <compiler angle="radian"></compiler>
  <visual>
    <global elevation="-30"></global>
  </visual>
  <extension>
    <plugin plugin="mujoco.pid">
      <instance name="slider-pid">
        <config key="kp" value="10.0"></config>
        <config key="ki" value="10"></config>
        <config key="kd" value="0.1"></config>
        <config key="imax" value="1"></config>
        <config key="slewmax" value="3"></config>
      </instance>
      <instance name="rotator-pid">
        <config key="kp" value="1"></config>
        <config key="ki" value="1"></config>
        <config key="kd" value="0.1"></config>
        <config key="imax" value="3"></config>
        <config key="slewmax" value="5"></config>
      </instance>
    </plugin>
    <plugin plugin="mujoco.elasticity.cable">
      <instance name="compositeguidewire">
        <config key="bend" value="5e9"></config>
        <config key="flat" value="true"></config>
        <config key="vmax" value="0.0004"></config>
      </instance>
      <instance name="compositetip">
        <config key="bend" value="1e9"></config>
        <config key="vmax" value="0.0004"></config>
      </instance>
    </plugin>
  </extension>
  <custom>
    <text data="rope_guidewire" name="composite_guidewire"></text>
    <text data="rope_tip" name="composite_tip"></text>
  </custom>
  <worldbody>
    <frame>
      <body name="guidewire" pos="0 -0.5 0.002" quat="0.707107 0 0 0.707107">
        <joint axis="1 0 0" damping="0.2" limited="true" name="slider" pos="0 0 0" range="-0.1 0.1" type="slide"></joint>
        <joint axis="1 0 0" damping="0.2" limited="false" name="rotator" pos="0 0 0" range="-3.14 3.14"></joint>
        <body name="guidewireB_first">
          <geom condim="1" name="guidewireG0" pos="0.00862069 0 0" quat="0.707107 0 -0.707107 0" rgba="1 0 0 1" size="0.00089 0.00862069" type="capsule"></geom>
          <site group="3" name="guidewireS_first" pos="0 0 0"></site>
          <plugin instance="compositeguidewire"></plugin>
          <body name="guidewireB_1" pos="0.0172414 0 0">
            <joint actuatorfrclimited="false" damping="0.001" group="3" name="guidewireJ_1" pos="0 0 0" type="ball"></joint>
            <geom condim="1" name="guidewireG1" pos="0.00862069 0 0" quat="0.707107 0 -0.707107 0" rgba="1 0 0 1" size="0.00089 0.00862069" type="capsule"></geom>
            <plugin instance="compositeguidewire"></plugin>
            <body name="guidewireB_2" pos="0.0172414 0 0">
              <joint actuatorfrclimited="false" damping="0.001" group="3" name="guidewireJ_2" pos="0 0 0" type="ball"></joint>
              <geom condim="1" name="guidewireG2" pos="0.00862069 0 0" quat="0.707107 0 -0.707107 0" rgba="1 0 0 1" size="0.00089 0.00862069" type="capsule"></geom>
              <plugin instance="compositeguidewire"></plugin>
              <body name="guidewireB_3" pos="0.0172414 0 0">
                <joint actuatorfrclimited="false" damping="0.001" group="3" name="guidewireJ_3" pos="0 0 0" type="ball"></joint>
                <geom condim="1" name="guidewireG3" pos="0.00862069 0 0" quat="0.707107 0 -0.707107 0" rgba="1 0 0 1" size="0.00089 0.00862069" type="capsule"></geom>
                <plugin instance="compositeguidewire"></plugin>
                <body name="guidewireB_4" pos="0.0172414 0 0">
                  <joint actuatorfrclimited="false" damping="0.001" group="3" name="guidewireJ_4" pos="0 0 0" type="ball"></joint>
                  <geom condim="1" name="guidewireG4" pos="0.00862069 0 0" quat="0.707107 0 -0.707107 0" rgba="1 0 0 1" size="0.00089 0.00862069" type="capsule"></geom>
                  <plugin instance="compositeguidewire"></plugin>
                  <body name="guidewireB_5" pos="0.0172414 0 0">
                    <joint actuatorfrclimited="false" damping="0.001" group="3" name="guidewireJ_5" pos="0 0 0" type="ball"></joint>
                    <geom condim="1" name="guidewireG5" pos="0.00862069 0 0" quat="0.707107 0 -0.707107 0" rgba="1 0 0 1" size="0.00089 0.00862069" type="capsule"></geom>
                    <plugin instance="compositeguidewire"></plugin>
                    <body name="guidewireB_6" pos="0.0172414 0 0">
                      <joint actuatorfrclimited="false" damping="0.001" group="3" name="guidewireJ_6" pos="0 0 0" type="ball"></joint>
                      <geom condim="1" name="guidewireG6" pos="0.00862069 0 0" quat="0.707107 0 -0.707107 0" rgba="1 0 0 1" size="0.00089 0.00862069" type="capsule"></geom>
                      <plugin instance="compositeguidewire"></plugin>
                      <body name="guidewireB_7" pos="0.0172414 0 0">
                        <joint actuatorfrclimited="false" damping="0.001" group="3" name="guidewireJ_7" pos="0 0 0" type="ball"></joint>
                        <geom condim="1" name="guidewireG7" pos="0.00862069 0 0" quat="0.707107 0 -0.707107 0" rgba="1 0 0 1" size="0.00089 0.00862069" type="capsule"></geom>
                        <plugin instance="compositeguidewire"></plugin>
                        <body name="guidewireB_8" pos="0.0172414 0 0">
                          <joint actuatorfrclimited="false" damping="0.001" group="3" name="guidewireJ_8" pos="0 0 0" type="ball"></joint>
                          <geom condim="1" name="guidewireG8" pos="0.00862069 0 0" quat="0.707107 0 -0.707107 0" rgba="1 0 0 1" size="0.00089 0.00862069" type="capsule"></geom>
                          <plugin instance="compositeguidewire"></plugin>
                          <body name="guidewireB_9" pos="0.0172414 0 0">
                            <joint actuatorfrclimited="false" damping="0.001" group="3" name="guidewireJ_9" pos="0 0 0" type="ball"></joint>
                            <geom condim="1" name="guidewireG9" pos="0.00862069 0 0" quat="0.707107 0 -0.707107 0" rgba="1 0 0 1" size="0.00089 0.00862069" type="capsule"></geom>
                            <plugin instance="compositeguidewire"></plugin>
                            <body name="guidewireB_10" pos="0.0172414 0 0">
                              <joint actuatorfrclimited="false" damping="0.001" group="3" name="guidewireJ_10" pos="0 0 0" type="ball"></joint>
                              <geom condim="1" name="guidewireG10" pos="0.00862069 0 0" quat="0.707107 0 -0.707107 0" rgba="1 0 0 1" size="0.00089 0.00862069" type="capsule"></geom>
                              <plugin instance="compositeguidewire"></plugin>
                              <body name="guidewireB_11" pos="0.0172414 0 0">
                                <joint actuatorfrclimited="false" damping="0.001" group="3" name="guidewireJ_11" pos="0 0 0" type="ball"></joint>
                                <geom condim="1" name="guidewireG11" pos="0.00862069 0 0" quat="0.707107 0 -0.707107 0" rgba="1 0 0 1" size="0.00089 0.00862069" type="capsule"></geom>
                                <plugin instance="compositeguidewire"></plugin>
                                <body name="guidewireB_12" pos="0.0172414 0 0">
                                  <joint actuatorfrclimited="false" damping="0.001" group="3" name="guidewireJ_12" pos="0 0 0" type="ball"></joint>
                                  <geom condim="1" name="guidewireG12" pos="0.00862069 0 0" quat="0.707107 0 -0.707107 0" rgba="1 0 0 1" size="0.00089 0.00862069" type="capsule"></geom>
                                  <plugin instance="compositeguidewire"></plugin>
                                  <body name="guidewireB_13" pos="0.0172414 0 0">
                                    <joint actuatorfrclimited="false" damping="0.001" group="3" name="guidewireJ_13" pos="0 0 0" type="ball"></joint>
                                    <geom condim="1" name="guidewireG13" pos="0.00862069 0 0" quat="0.707107 0 -0.707107 0" rgba="1 0 0 1" size="0.00089 0.00862069" type="capsule"></geom>
                                    <plugin instance="compositeguidewire"></plugin>
                                    <body name="guidewireB_14" pos="0.0172414 0 0">
                                      <joint actuatorfrclimited="false" damping="0.001" group="3" name="guidewireJ_14" pos="0 0 0" type="ball"></joint>
                                      <geom condim="1" name="guidewireG14" pos="0.00862069 0 0" quat="0.707107 0 -0.707107 0" rgba="1 0 0 1" size="0.00089 0.00862069" type="capsule"></geom>
                                      <plugin instance="compositeguidewire"></plugin>
                                      <body name="guidewireB_15" pos="0.0172414 0 0">
                                        <joint actuatorfrclimited="false" damping="0.001" group="3" name="guidewireJ_15" pos="0 0 0" type="ball"></joint>
                                        <geom condim="1" name="guidewireG15" pos="0.00862069 0 0" quat="0.707107 0 -0.707107 0" rgba="1 0 0 1" size="0.00089 0.00862069" type="capsule"></geom>
                                        <plugin instance="compositeguidewire"></plugin>
                                        <body name="guidewireB_16" pos="0.0172414 0 0">
                                          <joint actuatorfrclimited="false" damping="0.001" group="3" name="guidewireJ_16" pos="0 0 0" type="ball"></joint>
                                          <geom condim="1" name="guidewireG16" pos="0.00862069 0 0" quat="0.707107 0 -0.707107 0" rgba="1 0.167268 0 1" size="0.00089 0.00862069" type="capsule"></geom>
                                          <plugin instance="compositeguidewire"></plugin>
                                          <body name="guidewireB_17" pos="0.0172414 0 0">
                                            <joint actuatorfrclimited="false" damping="0.001" group="3" name="guidewireJ_17" pos="0 0 0" type="ball"></joint>
                                            <geom condim="1" name="guidewireG17" pos="0.00862068 0 0" quat="0.707107 0 -0.707107 0" rgba="1 0.756721 0 1" size="0.00089 0.00862068" type="capsule"></geom>
                                            <plugin instance="compositeguidewire"></plugin>
                                            <body name="guidewireB_18" pos="0.0172414 0 0">
                                              <joint actuatorfrclimited="false" damping="0.001" group="3" name="guidewireJ_18" pos="0 0 0" type="ball"></joint>
                                              <geom condim="1" name="guidewireG18" pos="0.00862069 0 0" quat="0.707107 0 -0.707107 0" rgba="0.71007 1 0 1" size="0.00089 0.00862069" type="capsule"></geom>
                                              <plugin instance="compositeguidewire"></plugin>
                                              <body name="guidewireB_19" pos="0.0172414 0 0">
                                                <joint actuatorfrclimited="false" damping="0.001" group="3" name="guidewireJ_19" pos="0 0 0" type="ball"></joint>
                                                <geom condim="1" name="guidewireG19" pos="0.00862069 0 0" quat="0.707107 0 -0.707107 0" rgba="0.228954 1 0 1" size="0.00089 0.00862069" type="capsule"></geom>
                                                <plugin instance="compositeguidewire"></plugin>
                                                <body name="guidewireB_20" pos="0.0172414 0 0">
                                                  <joint actuatorfrclimited="false" damping="0.001" group="3" name="guidewireJ_20" pos="0 0 0" type="ball"></joint>
                                                  <geom condim="1" name="guidewireG20" pos="0.00862068 0 0" quat="0.707107 0 -0.707107 0" rgba="0 1 0.203153 1" size="0.00089 0.00862068" type="capsule"></geom>
                                                  <plugin instance="compositeguidewire"></plugin>
                                                  <body name="guidewireB_21" pos="0.0172414 0 0">
                                                    <joint actuatorfrclimited="false" damping="0.001" group="3" name="guidewireJ_21" pos="0 0 0" type="ball"></joint>
                                                    <geom condim="1" name="guidewireG21" pos="0.00862069 0 0" quat="0.707107 0 -0.707107 0" rgba="0 1 0.58836 1" size="0.00089 0.00862069" type="capsule"></geom>
                                                    <plugin instance="compositeguidewire"></plugin>
                                                    <body name="guidewireB_22" pos="0.0172414 0 0">
                                                      <joint actuatorfrclimited="false" damping="0.001" group="3" name="guidewireJ_22" pos="0 0 0" type="ball"></joint>
                                                      <geom condim="1" name="guidewireG22" pos="0.00862069 0 0" quat="0.707107 0 -0.707107 0" rgba="0 1 0.927889 1" size="0.00089 0.00862069" type="capsule"></geom>
                                                      <plugin instance="compositeguidewire"></plugin>
                                                      <body name="guidewireB_23" pos="0.0172414 0 0">
                                                        <joint actuatorfrclimited="false" damping="0.001" group="3" name="guidewireJ_23" pos="0 0 0" type="ball"></joint>
                                                        <geom condim="1" name="guidewireG23" pos="0.00862069 0 0" quat="0.707107 0 -0.707107 0" rgba="0 0.777833 1 1" size="0.00089 0.00862069" type="capsule"></geom>
                                                        <plugin instance="compositeguidewire"></plugin>
                                                        <body name="guidewireB_24" pos="0.0172414 0 0">
                                                          <joint actuatorfrclimited="false" damping="0.001" group="3" name="guidewireJ_24" pos="0 0 0" type="ball"></joint>
                                                          <geom condim="1" name="guidewireG24" pos="0.00862068 0 0" quat="0.707107 0 -0.707107 0" rgba="0 0.529075 1 1" size="0.00089 0.00862068" type="capsule"></geom>
                                                          <plugin instance="compositeguidewire"></plugin>
                                                          <body name="guidewireB_25" pos="0.0172414 0 0">
                                                            <joint actuatorfrclimited="false" damping="0.001" group="3" name="guidewireJ_25" pos="0 0 0" type="ball"></joint>
                                                            <geom condim="1" name="guidewireG25" pos="0.00862069 0 0" quat="0.707107 0 -0.707107 0" rgba="0 0.326708 1 1" size="0.00089 0.00862069" type="capsule"></geom>
                                                            <plugin instance="compositeguidewire"></plugin>
                                                            <body name="guidewireB_26" pos="0.0172414 0 0">
                                                              <joint actuatorfrclimited="false" damping="0.001" group="3" name="guidewireJ_26" pos="0 0 0" type="ball"></joint>
                                                              <geom condim="1" name="guidewireG26" pos="0.00862069 0 0" quat="0.707107 0 -0.707107 0" rgba="0 0.172106 1 1" size="0.00089 0.00862069" type="capsule"></geom>
                                                              <plugin instance="compositeguidewire"></plugin>
                                                              <body name="guidewireB_27" pos="0.0172414 0 0">
                                                                <joint actuatorfrclimited="false" damping="0.001" group="3" name="guidewireJ_27" pos="0 0 0" type="ball"></joint>
                                                                <geom condim="1" name="guidewireG27" pos="0.00862068 0 0" quat="0.707107 0 -0.707107 0" rgba="0 0.0670392 1 1" size="0.00089 0.00862068" type="capsule"></geom>
                                                                <plugin instance="compositeguidewire"></plugin>
                                                                <body name="guidewireB_last" pos="0.0172414 0 0">
                                                                  <joint actuatorfrclimited="false" damping="0.001" group="3" name="guidewireJ_last" pos="0 0 0" type="ball"></joint>
                                                                  <geom condim="1" name="guidewireG28" pos="0.00862069 0 0" quat="0.707107 0 -0.707107 0" rgba="0 0.027132 1 1" size="0.00089 0.00862069" type="capsule"></geom>
                                                                  <site group="3" name="guidewireS_last" pos="0.0172414 0 0"></site>
                                                                  <plugin instance="compositeguidewire"></plugin>
                                                                  <body name="tip" pos="0.0172414 0 0 " quat="0.707107 0 0 -0.707107">
                                                                    <body name="tipB_first" quat="0.707695 0 0 0.706518">
                                                                      <geom condim="1" name="tipG0" pos="0.002704 0 0" quat="0.707107 0 -0.707107 0" rgba="0 0.192687 1 1" size="0.00089 0.002704" type="capsule"></geom>
                                                                      <site group="3" name="tipS_first" pos="0 0 0"></site>
                                                                      <plugin instance="compositetip"></plugin>
                                                                      <body name="tipB_1" pos="0.00540801 0 0" quat="1 0 0 0.000229109">
                                                                        <joint actuatorfrclimited="false" damping="0.001" group="3" name="tipJ_1" pos="0 0 0" type="ball"></joint>
                                                                        <geom condim="1" name="tipG1" pos="0.002073 0 0" quat="0.707107 0 -0.707107 0" rgba="0 0.167429 1 1" size="0.00089 0.002073" type="capsule"></geom>
                                                                        <plugin instance="compositetip"></plugin>
                                                                        <body name="tipB_2" pos="0.004146 0 0" quat="1 0 0 0.000440283">
                                                                          <joint actuatorfrclimited="false" damping="0.001" group="3" name="tipJ_2" pos="0 0 0" type="ball"></joint>
                                                                          <geom condim="1" name="tipG2" pos="0.0015365 0 0" quat="0.707107 0 -0.707107 0" rgba="0 0.125167 1 1" size="0.00089 0.0015365" type="capsule"></geom>
                                                                          <plugin instance="compositetip"></plugin>
                                                                          <body name="tipB_3" pos="0.003073 0 0" quat="1 0 0 0.000619746">
                                                                            <joint actuatorfrclimited="false" damping="0.001" group="3" name="tipJ_3" pos="0 0 0" type="ball"></joint>
                                                                            <geom condim="1" name="tipG3" pos="0.001094 0 0" quat="0.707107 0 -0.707107 0" rgba="0 0.0970689 1 1" size="0.00089 0.001094" type="capsule"></geom>
                                                                            <plugin instance="compositetip"></plugin>
                                                                            <body name="tipB_4" pos="0.002188 0 0" quat="1 0 0 0.000546304">
                                                                              <joint actuatorfrclimited="false" damping="0.001" group="3" name="tipJ_4" pos="0 0 0" type="ball"></joint>
                                                                              <geom condim="1" name="tipG4" pos="0.000747502 0 0" quat="0.707107 0 -0.707107 0" rgba="0 0.0789626 1 1" size="0.00089 0.000747502" type="capsule"></geom>
                                                                              <plugin instance="compositetip"></plugin>
                                                                              <body name="tipB_5" pos="0.001495 0 0" quat="0.999999 0 0 0.00152189">
                                                                                <joint actuatorfrclimited="false" damping="0.001" group="3" name="tipJ_5" pos="0 0 0" type="ball"></joint>
                                                                                <geom condim="1" name="tipG5" pos="0.000495006 0 0" quat="0.707107 0 -0.707107 0" rgba="0 0.0676064 1 1" size="0.00089 0.000495006" type="capsule"></geom>
                                                                                <plugin instance="compositetip"></plugin>
                                                                                <body name="tipB_6" pos="0.000990012 0 0" quat="1 0 0 0.000442092">
                                                                                  <joint actuatorfrclimited="false" damping="0.001" group="3" name="tipJ_6" pos="0 0 0" type="ball"></joint>
                                                                                  <geom condim="1" name="tipG6" pos="0.000337006 0 0" quat="0.707107 0 -0.707107 0" rgba="0 0.0604585 1 1" size="0.00089 0.000337006" type="capsule"></geom>
                                                                                  <plugin instance="compositetip"></plugin>
                                                                                  <body name="tipB_7" pos="0.000674012 0 0" quat="1 0 0 -0.00023511">
                                                                                    <joint actuatorfrclimited="false" damping="0.001" group="3" name="tipJ_7" pos="0 0 0" type="ball"></joint>
                                                                                    <geom condim="1" name="tipG7" pos="0.000274504 0 0" quat="0.707107 0 -0.707107 0" rgba="0 0.0554532 1 1" size="0.00089 0.000274504" type="capsule"></geom>
                                                                                    <plugin instance="compositetip"></plugin>
                                                                                    <body name="tipB_8" pos="0.000549008 0 0" quat="0.999996 0 0 -0.00273221">
                                                                                      <joint actuatorfrclimited="false" damping="0.001" group="3" name="tipJ_8" pos="0 0 0" type="ball"></joint>
                                                                                      <geom condim="1" name="tipG8" pos="0.000306 0 0" quat="0.707107 0 -0.707107 0" rgba="0 0.0509239 1 1" size="0.00089 0.000306" type="capsule"></geom>
                                                                                      <plugin instance="compositetip"></plugin>
                                                                                      <body name="tipB_9" pos="0.000612 0 0" quat="0.999999 0 0 -0.00115607">
                                                                                        <joint actuatorfrclimited="false" damping="0.001" group="3" name="tipJ_9" pos="0 0 0" type="ball"></joint>
                                                                                        <geom condim="1" name="tipG9" pos="0.000432501 0 0" quat="0.707107 0 -0.707107 0" rgba="0 0.0458994 1 1" size="0.00089 0.000432501" type="capsule"></geom>
                                                                                        <plugin instance="compositetip"></plugin>
                                                                                        <body name="tipB_10" pos="0.000865002 0 0" quat="0.999544 0 0 0.0301886">
                                                                                          <joint actuatorfrclimited="false" damping="0.001" group="3" name="tipJ_10" pos="0 0 0" type="ball"></joint>
                                                                                          <geom condim="1" name="tipG10" pos="0.00099067 0 0" quat="0.707107 0 -0.707107 0" rgba="0 0.0380466 1 1" size="0.00089 0.00099067" type="capsule"></geom>
                                                                                          <plugin instance="compositetip"></plugin>
                                                                                          <body name="tipB_11" pos="0.00198134 0 0" quat="0.997196 0 0 0.0748379">
                                                                                            <joint actuatorfrclimited="false" damping="0.001" group="3" name="tipJ_11" pos="0 0 0" type="ball"></joint>
                                                                                            <geom condim="1" name="tipG11" pos="0.000850308 0 0" quat="0.707107 0 -0.707107 0" rgba="0 0.0295284 1 1" size="0.00089 0.000850308" type="capsule"></geom>
                                                                                            <plugin instance="compositetip"></plugin>
                                                                                            <body name="tipB_12" pos="0.00170062 0 0" quat="0.995725 0 0 0.0923696">
                                                                                              <joint actuatorfrclimited="false" damping="0.001" group="3" name="tipJ_12" pos="0 0 0" type="ball"></joint>
                                                                                              <geom condim="1" name="tipG12" pos="0.000749617 0 0" quat="0.707107 0 -0.707107 0" rgba="0 0.0235951 1 1" size="0.00089 0.000749617" type="capsule"></geom>
                                                                                              <plugin instance="compositetip"></plugin>
                                                                                              <body name="tipB_13" pos="0.00149923 0 0" quat="0.994725 0 0 0.102582">
                                                                                                <joint actuatorfrclimited="false" damping="0.001" group="3" name="tipJ_13" pos="0 0 0" type="ball"></joint>
                                                                                                <geom condim="1" name="tipG13" pos="0.000692304 0 0" quat="0.707107 0 -0.707107 0" rgba="0 0.0188397 1 1" size="0.00089 0.000692304" type="capsule"></geom>
                                                                                                <plugin instance="compositetip"></plugin>
                                                                                                <body name="tipB_14" pos="0.00138461 0 0" quat="0.994763 0 0 0.102211">
                                                                                                  <joint actuatorfrclimited="false" damping="0.001" group="3" name="tipJ_14" pos="0 0 0" type="ball"></joint>
                                                                                                  <geom condim="1" name="tipG14" pos="0.000675394 0 0" quat="0.707107 0 -0.707107 0" rgba="0 0.0145419 1 1" size="0.00089 0.000675394" type="capsule"></geom>
                                                                                                  <plugin instance="compositetip"></plugin>
                                                                                                  <body name="tipB_15" pos="0.00135079 0 0" quat="0.996096 0 0 0.088279">
                                                                                                    <joint actuatorfrclimited="false" damping="0.001" group="3" name="tipJ_15" pos="0 0 0" type="ball"></joint>
                                                                                                    <geom condim="1" name="tipG15" pos="0.000691159 0 0" quat="0.707107 0 -0.707107 0" rgba="0 0.010494 1 1" size="0.00089 0.000691159" type="capsule"></geom>
                                                                                                    <plugin instance="compositetip"></plugin>
                                                                                                    <body name="tipB_16" pos="0.00138232 0 0" quat="0.997624 0 0 0.0688947">
                                                                                                      <joint actuatorfrclimited="false" damping="0.001" group="3" name="tipJ_16" pos="0 0 0" type="ball"></joint>
                                                                                                      <geom condim="1" name="tipG16" pos="0.000729 0 0" quat="0.707107 0 -0.707107 0" rgba="0 0.00682259 1 1" size="0.00089 0.000729" type="capsule"></geom>
                                                                                                      <plugin instance="compositetip"></plugin>
                                                                                                      <body name="tipB_17" pos="0.001458 0 0" quat="0.99882 0 0 0.0485588">
                                                                                                        <joint actuatorfrclimited="false" damping="0.001" group="3" name="tipJ_17" pos="0 0 0" type="ball"></joint>
                                                                                                        <geom condim="1" name="tipG17" pos="0.00077663 0 0" quat="0.707107 0 -0.707107 0" rgba="0 0.00375728 1 1" size="0.00089 0.00077663" type="capsule"></geom>
                                                                                                        <plugin instance="compositetip"></plugin>
                                                                                                        <body name="tipB_18" pos="0.00155326 0 0" quat="0.999543 0 0 0.0302407">
                                                                                                          <joint actuatorfrclimited="false" damping="0.001" group="3" name="tipJ_18" pos="0 0 0" type="ball"></joint>
                                                                                                          <geom condim="1" name="tipG18" pos="0.000829914 0 0" quat="0.707107 0 -0.707107 0" rgba="0 0.00152096 1 1" size="0.00089 0.000829914" type="capsule"></geom>
                                                                                                          <plugin instance="compositetip"></plugin>
                                                                                                          <body name="tipB_last" pos="0.00165983 0 0" quat="0.99987 0 0 0.0161458">
                                                                                                            <joint actuatorfrclimited="false" damping="0.001" group="3" name="tipJ_last" pos="0 0 0" type="ball"></joint>
                                                                                                            <geom condim="1" name="tipG19" pos="0.000882851 0 0" quat="0.707107 0 -0.707107 0" rgba="0 0.000635774 1 1" size="0.00089 0.000882851" type="capsule"></geom>
                                                                                                            <site group="3" name="tipS_last" pos="0.0017657 0 0"></site>
                                                                                                            <plugin instance="compositetip"></plugin>
                                                                                                          </body>
                                                                                                        </body>
                                                                                                      </body>
                                                                                                    </body>
                                                                                                  </body>
                                                                                                </body>
                                                                                              </body>
                                                                                            </body>
                                                                                          </body>
                                                                                        </body>
                                                                                      </body>
                                                                                    </body>
                                                                                  </body>
                                                                                </body>
                                                                              </body>
                                                                            </body>
                                                                          </body>
                                                                        </body>
                                                                      </body>
                                                                    </body>
                                                                  </body>
                                                                </body>
                                                              </body>
                                                            </body>
                                                          </body>
                                                        </body>
                                                      </body>
                                                    </body>
                                                  </body>
                                                </body>
                                              </body>
                                            </body>
                                          </body>
                                        </body>
                                      </body>
                                    </body>
                                  </body>
                                </body>
                              </body>
                            </body>
                          </body>
                        </body>
                      </body>
                    </body>
                  </body>
                </body>
              </body>
            </body>
          </body>
        </body>
      </body>
    </frame>
    <frame></frame>
  </worldbody>
  <contact>
    <exclude body1="guidewireB_first" body2="guidewireB_1"></exclude>
    <exclude body1="guidewireB_1" body2="guidewireB_2"></exclude>
    <exclude body1="guidewireB_2" body2="guidewireB_3"></exclude>
    <exclude body1="guidewireB_3" body2="guidewireB_4"></exclude>
    <exclude body1="guidewireB_4" body2="guidewireB_5"></exclude>
    <exclude body1="guidewireB_5" body2="guidewireB_6"></exclude>
    <exclude body1="guidewireB_6" body2="guidewireB_7"></exclude>
    <exclude body1="guidewireB_7" body2="guidewireB_8"></exclude>
    <exclude body1="guidewireB_8" body2="guidewireB_9"></exclude>
    <exclude body1="guidewireB_9" body2="guidewireB_10"></exclude>
    <exclude body1="guidewireB_10" body2="guidewireB_11"></exclude>
    <exclude body1="guidewireB_11" body2="guidewireB_12"></exclude>
    <exclude body1="guidewireB_12" body2="guidewireB_13"></exclude>
    <exclude body1="guidewireB_13" body2="guidewireB_14"></exclude>
    <exclude body1="guidewireB_14" body2="guidewireB_15"></exclude>
    <exclude body1="guidewireB_15" body2="guidewireB_16"></exclude>
    <exclude body1="guidewireB_16" body2="guidewireB_17"></exclude>
    <exclude body1="guidewireB_17" body2="guidewireB_18"></exclude>
    <exclude body1="guidewireB_18" body2="guidewireB_19"></exclude>
    <exclude body1="guidewireB_19" body2="guidewireB_20"></exclude>
    <exclude body1="guidewireB_20" body2="guidewireB_21"></exclude>
    <exclude body1="guidewireB_21" body2="guidewireB_22"></exclude>
    <exclude body1="guidewireB_22" body2="guidewireB_23"></exclude>
    <exclude body1="guidewireB_23" body2="guidewireB_24"></exclude>
    <exclude body1="guidewireB_24" body2="guidewireB_25"></exclude>
    <exclude body1="guidewireB_25" body2="guidewireB_26"></exclude>
    <exclude body1="guidewireB_26" body2="guidewireB_27"></exclude>
    <exclude body1="guidewireB_27" body2="guidewireB_last"></exclude>
    <exclude body1="tipB_first" body2="tipB_1"></exclude>
    <exclude body1="tipB_1" body2="tipB_2"></exclude>
    <exclude body1="tipB_2" body2="tipB_3"></exclude>
    <exclude body1="tipB_3" body2="tipB_4"></exclude>
    <exclude body1="tipB_4" body2="tipB_5"></exclude>
    <exclude body1="tipB_5" body2="tipB_6"></exclude>
    <exclude body1="tipB_6" body2="tipB_7"></exclude>
    <exclude body1="tipB_7" body2="tipB_8"></exclude>
    <exclude body1="tipB_8" body2="tipB_9"></exclude>
    <exclude body1="tipB_9" body2="tipB_10"></exclude>
    <exclude body1="tipB_10" body2="tipB_11"></exclude>
    <exclude body1="tipB_11" body2="tipB_12"></exclude>
    <exclude body1="tipB_12" body2="tipB_13"></exclude>
    <exclude body1="tipB_13" body2="tipB_14"></exclude>
    <exclude body1="tipB_14" body2="tipB_15"></exclude>
    <exclude body1="tipB_15" body2="tipB_16"></exclude>
    <exclude body1="tipB_16" body2="tipB_17"></exclude>
    <exclude body1="tipB_17" body2="tipB_18"></exclude>
    <exclude body1="tipB_18" body2="tipB_last"></exclude>
  </contact>
  <actuator>
    <plugin actdim="2" ctrlrange="-0.1 0.1" instance="slider-pid" joint="slider"></plugin>
    <plugin actdim="2" ctrlrange="-12.56 12.56" instance="rotator-pid" joint="rotator"></plugin>
    <!-- <general biasprm="0 0.1 0" dynprm="1 0 0" gainprm="0.1 0 0" gaintype="fixed" joint="rotator" name="rotator_actuator"></general> -->
  </actuator>
</mujoco>
