<mujoco model="guidewire">

  <compiler angle="degree" />

  <default>
    <default class="guidewire">
      <geom condim="4" rgba="0.1 0.1 0.1 1" margin="3e-3" />
    </default>

    <default class="tip">
      <geom condim="4" rgba="0.1 0.1 0.1 1" margin="3e-3" />
    </default>
  </default>

  <extension>
    <plugin plugin="mujoco.elasticity.cable">
      <instance name="compositeguidewire">
        <config key="bend" value="2e8" />
        <config key="vmax" value="0.05" />
      </instance>
      <instance name="compositetip">
        <config key="bend" value="5e6" />
        <config key="vmax" value="0.05" />
      </instance>
    </plugin>
  </extension>

  <actuator>
    <position name="slider" joint="slider" kp="60" kv="0" timeconst="0.1" inheritrange="0.9"
      forcerange="-0.1 0.1" />
    <position name="rotator" joint="rotator" kp="100" kv="0" timeconst="0.1" forcerange="-10 10" />
  </actuator>

  <worldbody>
    <frame>
      <body name="guidewire" childclass="guidewire" euler="0 0 90" pos="0 -.3 0.002">
        <joint name="slider" pos="0 0 0" axis="1 0 0" type="slide" limited="true" range="-0.2 0.2"
          damping="5" />
        <joint name="rotator" pos="0 0 0" axis="1 0 0" damping="5" />
        <composite count="30" curve="s" initial="none" prefix="guidewire" size="0.25" type="cable">
          <plugin instance="compositeguidewire"></plugin>
          <joint damping=".015" kind="main"></joint>
          <geom type="capsule" size=".000445" />
        </composite>
        <body name="tip" childclass="tip" euler="0 0 -90" pos="0.25 0 0">
          <composite initial="none" prefix="tip" type="cable"
            vertex=" 0.000000 -0.000000 0.000000 0.000009 0.005408 0.000000 0.000014 0.009554 0.000000 0.000015 0.012627 0.000000 0.000013 0.014815 0.000000 0.000010 0.016310 0.000000 0.000005 0.017300 0.000000 0.000001 0.017974 0.000000 -0.000002 0.018523 0.000000 -0.000002 0.019135 0.000000 0.000000 0.020000 0.000000 -0.000115 0.021978 0.000000 -0.000466 0.023642 0.000000 -0.001040 0.025027 0.000000 -0.001820 0.026171 0.000000 -0.002792 0.027109 0.000000 -0.003940 0.027879 0.000000 -0.005251 0.028517 0.000000 -0.006707 0.029058 0.000000 -0.008295 0.029541 0.000000 -0.010000 0.030000 0.000000 ">
            <plugin instance="compositetip"></plugin>
            <geom type="capsule" size=".000445" />
            <joint damping=".015" kind="main"></joint>
          </composite>
        </body>
      </body>
    </frame>
  </worldbody>
</mujoco>
