<mujoco model="guidewire">

  <compiler angle="degree" />

  <default>
    <default class="guidewire">
      <geom condim="4" rgba="0.1 0.1 0.1 1" margin="3e-3" />
    </default>

    <default class="tip">
      <geom condim="4" rgba="0.1 0.1 0.1 1" margin="3e-3" />
    </default>
  </default>

  <extension>
    <plugin plugin="mujoco.elasticity.cable">
      <instance name="compositeguidewire">
        <config key="bend" value="2e8" />
        <config key="vmax" value="0.05" />
      </instance>
    </plugin>
  </extension>

  <actuator>
    <position name="slider" joint="slider" kp="60" kv="0" timeconst="0.1" inheritrange="0.9"
      forcerange="-0.1 0.1" />
    <position name="rotator" joint="rotator" kp="100" kv="0" timeconst="0.1" forcerange="-10 10" />
  </actuator>

  <worldbody>
    <frame>
      <body name="guidewire" childclass="guidewire" euler="0 0 90" pos="0 -.3 0.002">
        <joint name="slider" pos="0 0 0" axis="1 0 0" type="slide" limited="true" range="-0.2 0.2"
          damping="5" />
        <joint name="rotator" pos="0 0 0" axis="1 0 0" damping="5" />
        <composite count="30" curve="s" initial="none" prefix="guidewire" size="0.25" type="cable">
          <plugin instance="compositeguidewire"></plugin>
          <joint damping=".015" kind="main"></joint>
          <geom type="capsule" size=".000445" />
        </composite>
      </body>
    </frame>
  </worldbody>
</mujoco>
